<?xml version="1.0"?>
<robot name="flat_taxi">
	
	<!-- rviz color scheme -->
	<material name="crusta">
  		<color rgba="0.99 0.52 0.20 1.00"/>
	</material>

	<material name="dovegray">
  		<color rgba="0.45 0.46 0.46 1.00"/>
	</material>

	<material name="white">
  		<color rgba="0.96 0.98 0.99 1.00"/>
	</material>

	<!-- fixed base -->
	<link name="footprint">
		<visual>
			<origin rpy="0 0 0" xyz="0 0 0"/>
			<geometry>
			  <box size="0.001 0.001 0.001"/>
			</geometry>
		</visual>
	</link>
	
	<!-- gazebo reference for the fixed base -->
	<gazebo reference="footprint">
		<turnGravityOff>false</turnGravityOff>
	</gazebo>
	
	<!-- footprint -> base_link joint -->
	<joint name="base_joint" type="fixed">
	  <origin rpy="0 0 0" xyz="0 0 0.2"/>
      <parent link="footprint"/>
      <child link="base_link"/>
    </joint>

    <!-- base link -->
    <link name="base_link">
		<inertial>
		    <mass value="5"/>
		    <origin xyz="0 0 0"/>
		    <inertia ixx="0.104167" ixy="0" ixz="0" iyy="0.416667" iyz="0" izz="0.520833"/>
		</inertial>
		<visual>
		    <origin rpy="0 0 0" xyz="0 0 0"/>
		    <geometry>
		     	<box size="1 0.5 0.25" />
		    </geometry>
		    <material name="white"/>
		</visual>
		<collision>
		    <origin rpy="0 0 0 " xyz="0 0 0"/>
		    <geometry>
		    	<box size="1 0.5 0.25" />
		    </geometry>
		</collision>
    </link>
	
	<!-- gazebo base_link reference -->
    <gazebo reference="base_link">
    	<turnGravityOff>false</turnGravityOff>
    </gazebo>

    <!-- wheel right -->
    <link name="right_wheel">
        <visual>
        	<!-- PI / 2 -->
			<origin rpy="1.57079632679 0 0" xyz="0 0 0"/>
            <geometry>
                <cylinder length="0.1" radius="0.2"/>
            </geometry>
			<material name="dovegray"/>
        </visual>
		<collision>
		  <origin rpy="1.57079632679 0 0 " xyz="0 0 0"/>
		  <geometry>
		    <cylinder length="0.1" radius="0.2"/>
		  </geometry>
		</collision>
		<inertial>
		  <mass value="1"/>
		  <!-- default inertial -->
		  <inertia ixx="1.0" ixy="0.0" ixz="0.0" iyy="1.0" iyz="0.0" izz="1.0"/>
		</inertial>
    </link>

    <!-- right wheel gazebo reference -->
	<gazebo reference="right_wheel">
		<mu1 value="200.0"/>
  		<mu2 value="100.0"/>
  		<kp value="10000000.0" />
  		<kd value="1.0" />
  		<material>Gazebo/Black</material>
      <turnGravityOff>false</turnGravityOff>
    </gazebo>

    <!-- First it with a 2 wheel car / place the wheel in the middle -->
   	<joint name="right_wheel_joint" type="continuous">
		<parent link="base_link"/>
	  	<child link="right_wheel"/>
	  	<origin rpy="0 0 0" xyz="0.0 0.30 0.0"/>
	  	<axis rpy="0 0 0" xyz="0 1 0"/>
	  	<limit effort="100" velocity="100"/>
	  	<joint_properties damping="0.0" friction="0.0"/>
    </joint>

    <transmission name="right_wheel_control">
  		<type>transmission_interface/SimpleTransmission</type>
  		<actuator name="right_wheel_motor">
			<mechanicalReduction>1</mechanicalReduction>
  		</actuator>
  		<joint name="right_wheel_joint">
			<hardwareInterface>hardware_interface/EffortJointInterface</hardwareInterface>
  		</joint>
	</transmission>
	
	<!-- left wheel -->
	<link name="left_wheel">
        <visual>
			<origin rpy="1.57079632679 0 0" xyz="0 0 0"/>
            <geometry>
                <cylinder length="0.1" radius="0.2"/>
            </geometry>
			<material name="dovegray"/>
        </visual>
		<collision>
		  <origin rpy="1.57079632679 0 0" xyz="0 0 0"/>
		  <geometry>
		    <cylinder length="0.1" radius="0.2"/>
		  </geometry>
		</collision>
		<inertial>
		  <mass value="1"/>
		  <inertia ixx="1.0" ixy="0.0" ixz="0.0" iyy="1.0" iyz="0.0" izz="1.0"/>
		</inertial>
    </link>

	<gazebo reference="left_wheel">
		<mu1 value="200.0"/>
    	<mu2 value="100.0"/>
    	<kp value="10000000.0" />
    	<kd value="1.0" />
    	<material>Gazebo/Black</material>
        <turnGravityOff>false</turnGravityOff>
    </gazebo>

	<joint name="left_wheel_joint" type="continuous">
	    <parent link="base_link"/>
	    <child link="left_wheel"/>
	    <origin rpy="0 0 0" xyz="0.0 -0.30 0.0"/>
	    <axis rpy="0 0 0" xyz="0 1 0"/>
	    <limit effort="100" velocity="100"/>
	    <joint_properties damping="0.0" friction="0.0"/>
	 </joint>

	<transmission name="left_wheel_control">
		<type>transmission_interface/SimpleTransmission</type>
		<actuator name="left_wheel_motor">
			<mechanicalReduction>1</mechanicalReduction>
		</actuator>
		<joint name="left_wheel_joint">
			<hardwareInterface>hardware_interface/EffortJointInterface</hardwareInterface>
		</joint>
	</transmission>


	<!-- front caster wheel for rotation  -->
	<link name="front_caster_wheel">
		<visual>
			<origin rpy="0 0 0" xyz="0 0 -0.1"/>
			<geometry>
                <sphere radius="0.1"/>
            </geometry>
			<material name="crusta"/>
		</visual>
		<collision>
			<origin rpy="0 0 0" xyz="0 0 -0.1"/>
			<geometry>
                <sphere radius="0.1"/>
            </geometry>
		</collision>
		<inertial>
			<origin xyz="0 0 0" />
			<mass value="1"/>
			<!-- default inertial -->
			<inertia ixx="1.0" ixy="0.0" ixz="0.0" iyy="1.0" iyz="0.0" izz="1.0"/>
		</inertial>
	</link>
	
	<!-- 1/5 length from the center -->
	<joint name="front_caster_wheel_joint" type="fixed">
		<parent link="base_link"/>
		<child link="front_caster_wheel"/>
		<origin rpy="0 0 0" xyz="0.4 0 0" />
	</joint>
	
	<!-- Front caster wheel gazebo reference -->
	<gazebo reference="front_caster_wheel">
		<mu1 value="0.0"/>
		<mu2 value="0.0"/>
		<turnGravityOff>false</turnGravityOff>
		<material>Gazebo/Black</material>
	</gazebo>

	<!-- front caster wheel for reverse rotation  -->
	<link name="back_caster_wheel">
		<visual>
			<origin rpy="0 0 0" xyz="0 0 -0.1"/>
			<geometry>
                <sphere radius="0.1"/>
            </geometry>
			<material name="crusta"/>
		</visual>
		<collision>
			<origin rpy="0 0 0" xyz="0 0 -0.1"/>
			<geometry>
                <sphere radius="0.1"/>
            </geometry>
		</collision>
		<inertial>
			<origin xyz="0 0 0" />
			<mass value="1"/>
			<!-- default inertial -->
			<inertia ixx="1.0" ixy="0.0" ixz="0.0" iyy="1.0" iyz="0.0" izz="1.0"/>
		</inertial>
	</link>
	
	<!-- -1/5 length from the center -->
	<joint name="back_caster_wheel_joint" type="fixed">
		<parent link="base_link"/>
		<child link="back_caster_wheel"/>
		<origin rpy="0 0 0" xyz="-0.4 0 0" />
	</joint>
	
	<!-- Back caster wheel gazebo reference -->
	<gazebo reference="back_caster_wheel">
		<mu1 value="0.0"/>
		<mu2 value="0.0"/>
		<turnGravityOff>false</turnGravityOff>
		<material>Gazebo/Black</material>
	</gazebo>

	<!-- +++++++++++++++++++++++++++++ sensors ++++++++++++++++++++++++++ -->
	
	<!-- ************************ Camera ******************************** -->
	<link name="camera">
	    <collision>
	    	<origin xyz="0 0 0" rpy="0 0 0"/>
	      	<geometry>
	   			<box size="0.1 0.5 0.1"/>
	      	</geometry>
	    </collision>

	    <visual>
	    	<origin xyz="0 0 0" rpy="0 0 0"/>
	      	<geometry>
	    		<box size="0.1 0.5 0.1"/>
	      	</geometry>
	      	<material name="crusta"/>
	    </visual>

		<inertial>
			<origin xyz="0 0 0" />
			<mass value="1"/>
			<!-- default inertial -->
			<inertia ixx="1.0" ixy="0.0" ixz="0.0" iyy="1.0" iyz="0.0" izz="1.0"/>
		</inertial>
	</link>

	<joint name="camera_joint" type="fixed">
	    <parent link="base_link"/>
	    <child link="camera"/>
	    <origin xyz="0.45 0.0 0.175" rpy="0 0 0"/>
	</joint>

  <!--Gazebo Camera Plugin-->
   <gazebo reference="camera">
	<material>Gazebo/Green</material>
    <sensor type="camera" name="camera">
      <update_rate>30.0</update_rate>
      <camera name="head">
        <horizontal_fov>1.3962634</horizontal_fov>
        <image>
          <width>640</width>
          <height>320</height>
          <format>R8G8B8</format>
        </image>
        <clip>
          <near>0.02</near>
          <far>300</far>
        </clip>
        <noise>
          <type>gaussian</type>
          <!-- Noise is sampled independently per pixel on each frame.
               That pixel's noise value is added to each of its color
               channels, which at that point lie in the range [0,1]. -->
          <mean>0.0</mean>
          <stddev>0.007</stddev>
        </noise>
      </camera>
      <plugin name="camera_controller" filename="libgazebo_ros_camera.so">
        <alwaysOn>true</alwaysOn>
        <updateRate>0.0</updateRate>
        <cameraName>/mybot/camera</cameraName>
        <imageTopicName>image_raw</imageTopicName>
        <cameraInfoTopicName>camera_info</cameraInfoTopicName>
        <frameName>camera</frameName>
        <hackBaseline>0.07</hackBaseline>
        <distortionK1>0.0</distortionK1>
        <distortionK2>0.0</distortionK2>
        <distortionK3>0.0</distortionK3>
        <distortionT1>0.0</distortionT1>
        <distortionT2>0.0</distortionT2>
      </plugin>
    </sensor>
  </gazebo>

	<!-- ************************ Camera ******************************** -->
	
	<!-- ************************ 2D range finder **********************  -->
	<link name="hokuyo_range_finder">
        <visual>
			<origin rpy="0 0 0" xyz="0 0 0"/>
            <geometry>
                <box size="0.1 0.1 0.1"/>
            </geometry>
			<material name="crusta"/>
        </visual>
    </link>
	
	<joint name="base_hokuyo_joint" type="fixed">
		<parent link="base_link"/>
		<child link="hokuyo_range_finder"/>
		<origin xyz="0.55 0.0 0.0" rpy="0 0 0" />
	</joint>

	<gazebo reference="hokuyo_range_finder">
    	<material>Gazebo/Blue</material>
	    <sensor name="head_hokuyo_sensor" type="ray">
	    	<pose>0.05 0 0 0 0 0</pose>
	      	<visualize>true</visualize>
	     	<update_rate>40</update_rate>
		    <ray>
		        <scan>
		        	<horizontal>
			            <samples>720</samples>
			            <resolution>1</resolution>
			            <min_angle>-1.570796</min_angle>
			            <max_angle>1.570796</max_angle>
		        	</horizontal>
		        </scan>
		        <range>
		          	<min>0.10</min>
		          	<max>10.0</max>
		        	<resolution>0.001</resolution>
		        </range>
		    </ray>
	      	<plugin filename="libgazebo_ros_laser.so" name="gazebo_hokuyo_controller">
	        	<topicName>/scan</topicName>
	        	<frameName>hokuyo_link</frameName>
	     	 </plugin>
	    </sensor>
  	</gazebo>

	<!-- ************************ 2D range finder **********************  -->
	<!-- +++++++++++++++++++++++++++++ sensors ++++++++++++++++++++++++++ -->



	<!-- Differential drive gazebo plugin -->
	<gazebo> 
		<plugin name="differential_drive_controller" filename="libgazebo_ros_diff_drive.so" >
			<alwaysOn>true</alwaysOn>
			<updateRate>100.0</updateRate>
			<leftJoint>left_wheel_joint</leftJoint>
			<rightJoint>right_wheel_joint</rightJoint>
			<wheelSeparation>0.5</wheelSeparation>
			<wheelDiameter>0.4</wheelDiameter>
			<broadcastTF>1</broadcastTF>
			<wheelTorque>30</wheelTorque>
			<wheelAcceleration>1.8</wheelAcceleration>
			<commandTopic>cmd_vel</commandTopic>
			<odometryFrame>odom</odometryFrame>
			<odometryTopic>odom</odometryTopic>
			<rosDebugLevel>Debug</rosDebugLevel>
			<publishWheelTF>false</publishWheelTF>
			<robotNamespace>/</robotNamespace>
			<publishTf>1</publishTf>
			<publishWheelJointState>false</publishWheelJointState>
			<robotBaseFrame>footprint</robotBaseFrame>
	  	</plugin>
	</gazebo>
	
	<gazebo>
	    <plugin name="gazebo_ros_control" filename="libgazebo_ros_control.so">
	      <robotNamespace>/</robotNamespace>
		  <robotSimType>gazebo_ros_control/DefaultRobotHWSim</robotSimType>
         <legacyModeNS>true</legacyModeNS>
	    </plugin>
  	</gazebo>

</robot>
